Workbook
Name Barang_OK01___Cilandak_Town_Square: Referensi!$C$1:$C$4
Name Barang_OK02___Pasar_Baru: Referensi!$C$17:$C$20
Name Barang_OK03___Kelapa_Gading: Referensi!$C$9:$C$11
Name Barang_OK04___Senopati: Referensi!$C$27:$C$29
Name Barang_OK05___Pondok_Indah: Referensi!$C$21:$C$23
Name Barang_OK07___Lebak_Bulus: Referensi!$C$14:$C$16
Name Barang_OK08___Ciputat: Referensi!$C$7:$C$8
Name Barang_OK09___Cipedak: Referensi!$C$5:$C$6
Name Barang_OK10___Kemang: Referensi!$C$12:$C$13
Name Barang_OK11___Rasuna_Said: Referensi!$C$24:$C$26
Name Diskon_OK01___Cilandak_Town_Square_MB01___Gulaku: Referensi!$E$2:$E$3
Name Diskon_OK01___Cilandak_Town_Square_MB02___Segitiga_Emas: Referensi!$E$4
Name Diskon_OK01___Cilandak_Town_Square_TST01___Barang_01: Referensi!$E$1
Name Diskon_OK01___Cilandak_Town_Square_TST02_upd___Test_lagi_upd: Referensi!$E$5:$E$6
Name Diskon_OK02___Pasar_Baru_MB01___Gulaku: Referensi!$E$26:$E$27
Name Diskon_OK02___Pasar_Baru_MB05___Harum_Manis: Referensi!$E$28:$E$29
Name Diskon_OK02___Pasar_Baru_TST01___Barang_01: Referensi!$E$25
Name Diskon_OK03___Kelapa_Gading_MB01___Gulaku: Referensi!$E$16:$E$17
Name Diskon_OK03___Kelapa_Gading_MB02___Segitiga_Emas: Referensi!$E$18
Name Diskon_OK03___Kelapa_Gading_TST01___Barang_01: Referensi!$E$15
Name Diskon_OK04___Senopati_MB01___Gulaku: Referensi!$E$39:$E$40
Name Diskon_OK04___Senopati_TST01___Barang_01: Referensi!$E$38
Name Diskon_OK04___Senopati_TST02_upd___Test_lagi_upd: Referensi!$E$41:$E$42
Name Diskon_OK05___Pondok_Indah_MB01___Gulaku: Referensi!$E$31:$E$32
Name Diskon_OK05___Pondok_Indah_TST01___Barang_01: Referensi!$E$30
Name Diskon_OK05___Pondok_Indah_TST02_upd___Test_lagi_upd: Referensi!$E$33:$E$34
Name Diskon_OK06___Tangerang_Selatan_MB01___Gulaku: Referensi!$E$44:$E$45
Name Diskon_OK06___Tangerang_Selatan_MB05___Harum_Manis: Referensi!$E$46:$E$47
Name Diskon_OK06___Tangerang_Selatan_TST01___Barang_01: Referensi!$E$43
Name Diskon_OK07___Lebak_Bulus_MB01___Gulaku: Referensi!$E$21:$E$22
Name Diskon_OK07___Lebak_Bulus_MB05___Harum_Manis: Referensi!$E$23:$E$24
Name Diskon_OK08___Ciputat_MB01___Gulaku: Referensi!$E$11:$E$12
Name Diskon_OK08___Ciputat_MB05___Harum_Manis: Referensi!$E$13:$E$14
Name Diskon_OK09___Cipedak_MB01___Gulaku: Referensi!$E$7:$E$8
Name Diskon_OK09___Cipedak_MB05___Harum_Manis: Referensi!$E$9:$E$10
Name Diskon_OK10___Kemang_MB01___Gulaku: Referensi!$E$19:$E$20
Name Diskon_OK11___Rasuna_Said_MB01___Gulaku: Referensi!$E$35:$E$36
Name Diskon_OK11___Rasuna_Said_MB02___Segitiga_Emas: Referensi!$E$37
Name Sales_OK01___Cilandak_Town_Square: Referensi!$B$1:$B$3
Name Sales_OK02___Pasar_Baru: Referensi!$B$13:$B$14
Name Sales_OK03___Kelapa_Gading: Referensi!$B$6:$B$10
Name Sales_OK04___Senopati: Referensi!$B$20
Name Sales_OK05___Pondok_Indah: Referensi!$B$15:$B$19
Name Sales_OK07___Lebak_Bulus: Referensi!$B$12
Name Sales_OK08___Ciputat: Referensi!$B$5
Name Sales_OK09___Cipedak: Referensi!$B$4
Name Sales_OK10___Kemang: Referensi!$B$11

Sheet Header
A1: Kode Penjualan | B1: Tanggal Penjualan | C1: Outlet | D1: Sales
A2: PJ-099 | B2: 45896 | C2: OK04 - Senopati | D2: S04 - Joko Irwandi | E2: <--- Contoh pengisian data
A3: TST | B3: 45901 | C3: OK03 - Kelapa Gading | D3: S13 - Toni

Sheet Detail
A1: Kode Penjualan | B1: Outlet | C1: Barang | D1: Harga | E1: Qty | F1: Diskon
A2: PJ-099 | B2: =IF(A2<>"",VLOOKUP(A2, Header!$A$2:$C$11, 3, 0),"") -> OK04 - Senopati | C2: MB01 - Gulaku | D2: =IF(C2<>"",VLOOKUP(C2, Referensi!$C$2:$D$33, 2, 0),"") -> 17000 | E2: 40 | F2: 20 @ 15000,00 | G2: <--- Contoh pengisian data
A3: TST | B3: =IF(A3<>"",VLOOKUP(A3, Header!$A$2:$C$11, 3, 0),"") -> OK03 - Kelapa Gading | C3: MB02 - Segitiga Emas | D3: =IF(C3<>"",VLOOKUP(C3, Referensi!$C$2:$D$33, 2, 0),"") -> 7000 | E3: 50 | F3: 10 @ 10000,00
B4: =IF(A4<>"",VLOOKUP(A4, Header!$A$2:$C$11, 3, 0),"") | D4: =IF(C4<>"",VLOOKUP(C4, Referensi!$C$2:$D$33, 2, 0),"")
B5: =IF(A5<>"",VLOOKUP(A5, Header!$A$2:$C$11, 3, 0),"") | D5: =IF(C5<>"",VLOOKUP(C5, Referensi!$C$2:$D$33, 2, 0),"")
B6: =IF(A6<>"",VLOOKUP(A6, Header!$A$2:$C$11, 3, 0),"") | D6: =IF(C6<>"",VLOOKUP(C6, Referensi!$C$2:$D$33, 2, 0),"")
B7: =IF(A7<>"",VLOOKUP(A7, Header!$A$2:$C$11, 3, 0),"") | D7: =IF(C7<>"",VLOOKUP(C7, Referensi!$C$2:$D$33, 2, 0),"")
B8: =IF(A8<>"",VLOOKUP(A8, Header!$A$2:$C$11, 3, 0),"") | D8: =IF(C8<>"",VLOOKUP(C8, Referensi!$C$2:$D$33, 2, 0),"")
B9: =IF(A9<>"",VLOOKUP(A9, Header!$A$2:$C$11, 3, 0),"") | D9: =IF(C9<>"",VLOOKUP(C9, Referensi!$C$2:$D$33, 2, 0),"")
B10: =IF(A10<>"",VLOOKUP(A10, Header!$A$2:$C$11, 3, 0),"") | D10: =IF(C10<>"",VLOOKUP(C10, Referensi!$C$2:$D$33, 2, 0),"")
B11: =IF(A11<>"",VLOOKUP(A11, Header!$A$2:$C$11, 3, 0),"") | D11: =IF(C11<>"",VLOOKUP(C11, Referensi!$C$2:$D$33, 2, 0),"")
B12: =IF(A12<>"",VLOOKUP(A12, Header!$A$2:$C$11, 3, 0),"") | D12: =IF(C12<>"",VLOOKUP(C12, Referensi!$C$2:$D$33, 2, 0),"")
B13: =IF(A13<>"",VLOOKUP(A13, Header!$A$2:$C$11, 3, 0),"") | D13: =IF(C13<>"",VLOOKUP(C13, Referensi!$C$2:$D$33, 2, 0),"")
B14: =IF(A14<>"",VLOOKUP(A14, Header!$A$2:$C$11, 3, 0),"") | D14: =IF(C14<>"",VLOOKUP(C14, Referensi!$C$2:$D$33, 2, 0),"")
B15: =IF(A15<>"",VLOOKUP(A15, Header!$A$2:$C$11, 3, 0),"") | D15: =IF(C15<>"",VLOOKUP(C15, Referensi!$C$2:$D$33, 2, 0),"")
... B30: =IF(A30<>"",VLOOKUP(A30, Header!$A$2:$C$11, 3, 0),"") | D30: =IF(C30<>"",VLOOKUP(C30, Referensi!$C$2:$D$33, 2, 0),"")

Sheet Referensi
A1: OK01 - Cilandak Town Square | B1: S05 - Fitri Hanif | C1: TST01 - Barang 01 | D1: 35000 | E1: 4 @ 60000,00
A2: OK09 - Cipedak | B2: S02 - Ilham Fachry | C2: MB01 - Gulaku | D2: 17000 | E2: 8 @ 4000,00
A3: OK08 - Ciputat | B3: S87 - Test upl benar 1 | C3: MB02 - Segitiga Emas | D3: 7000 | E3: 20 @ 15000,00
A4: OK03 - Kelapa Gading | B4: S06 - Pratiwi | C4: TST02 upd - Test lagi upd | D4: 8000 | E4: 10 @ 10000,00
A5: OK10 - Kemang | B5: S14 - Test | C5: MB01 - Gulaku | D5: 17000 | E5: 20 @ 16000,00
A6: OK07 - Lebak Bulus | B6: UPL01 - Test Upload 01 | C6: MB05 - Harum Manis | D6: 40000 | E6: 40 @ 32000,00
A7: OK02 - Pasar Baru | B7: UPL02 - Test Upload 02 | C7: MB01 - Gulaku | D7: 17000 | E7: 8 @ 4000,00
A8: OK05 - Pondok Indah | B8: UPL03 - Test Upload 03 | C8: MB05 - Harum Manis | D8: 40000 | E8: 20 @ 15000,00
A9: OK04 - Senopati | B9: S13 - Toni | C9: TST01 - Barang 01 | D9: 35000 | E9: 12 @ 30000,00
A10: OK06 - Tangerang Selatan | B10: S12 - Tono | C10: MB01 - Gulaku | D10: 17000 | E10: 24 @ 70000,00
B11: S08 - Fajar Julianto | C11: MB02 - Segitiga Emas | D11: 7000 | E11: 8 @ 4000,00
B12: S07 - Gunawan | C12: MB01 - Gulaku | D12: 17000 | E12: 20 @ 15000,00
B13: S01 - Ridwan | C13: MB04 - Snowman (Permanent) | D13: 13000 | E13: 12 @ 30000,00
B14: S09 - Victor Von Doom | C14: MB01 - Gulaku | D14: 17000 | E14: 24 @ 70000,00
B15: S03 - Doni Wahid | C15: MB05 - Harum Manis | D15: 40000 | E15: 4 @ 60000,00
B16: S11 - Indra Bekti | C16: MB04 - Snowman (Permanent) | D16: 13000 | E16: 8 @ 4000,00
B17: UPL04 - Test Upload 04 | C17: TST01 - Barang 01 | D17: 35000 | E17: 20 @ 15000,00
B18: UPL05 - Test Upload 05 | C18: MB01 - Gulaku | D18: 17000 | E18: 10 @ 10000,00
B19: UPL06 - Test Upload 06 | C19: MB05 - Harum Manis | D19: 40000 | E19: 8 @ 4000,00
B20: S04 - Joko Irwandi | C20: MB04 - Snowman (Permanent) | D20: 13000 | E20: 20 @ 15000,00
B21: UPL07 - Test Upload 07 | C21: TST01 - Barang 01 | D21: 35000 | E21: 8 @ 4000,00
B22: UPL08 - Test Upload 08 | C22: MB01 - Gulaku | D22: 17000 | E22: 20 @ 15000,00
... B24: UPL10 - Test Upload 10 | C24: MB01 - Gulaku | D24: 17000 | E24: 24 @ 70000,00
C25: MB02 - Segitiga Emas | D25: 7000 | E25: 4 @ 60000,00
C26: MB04 - Snowman (Permanent) | D26: 13000 | E26: 8 @ 4000,00
C27: TST01 - Barang 01 | D27: 35000 | E27: 20 @ 15000,00
C28: MB01 - Gulaku | D28: 17000 | E28: 12 @ 30000,00
C29: TST02 upd - Test lagi upd | D29: 8000 | E29: 24 @ 70000,00
C30: TST01 - Barang 01 | D30: 35000 | E30: 4 @ 60000,00
C31: MB01 - Gulaku | D31: 17000 | E31: 8 @ 4000,00
C32: MB05 - Harum Manis | D32: 40000 | E32: 20 @ 15000,00
C33: MB03 - Rojolele | D33: 98000 | E33: 20 @ 16000,00
E34: 40 @ 32000,00
E35: 8 @ 4000,00
E36: 20 @ 15000,00
E37: 10 @ 10000,00
E38: 4 @ 60000,00
E39: 8 @ 4000,00
E40: 20 @ 15000,00
E41: 20 @ 16000,00
...
